Workbook

Sheet Приход
F1: сумма: | G1: =SUM(E2:E18) -> 152210 | I1: сумма закупки: | J1: =SUM(G1:G74) -> 722198
A2: 1 | B2: EZ-HAC-B2A41P-0280B-DIP Видеокамера HDCVI купольная, 1/2.7" 4Мп | C2: 1 | D2: 1495 | E2: =C2*D2 -> 1495 | I2: взято на закупку: | J2: 700000
A3: 2 | B3: EZ-HAC-B6B20P-LED-0360B Видеокамера HDCVI цилиндрическая, 1/2.8" 2Мп | C3: 2 | D3: 1395 | E3: =C3*D3 -> 2790 | I3: остаток: | J3: =J2-J1 -> -22198
A4: 3 | B4: EZ-HAC-D1A21P-0280B 2Мп HD-CVI камера видеонаблюдения | C4: 10 | D4: 995 | E4: =C4*D4 -> 9950
A5: 4 | B5: EZ-HAC-D1A41P-0280B 4Мп HDCVI видеокамера | C5: 5 | D5: 1395 | E5: =C5*D5 -> 6975
A6: 5 | B6: EZ-HAC-D1A41P-0360B 4Мп HDCVI видеокамера | C6: 5 | D6: 1395 | E6: =C6*D6 -> 6975
A7: 6 | B7: EZ-HAC-T2A11P-0280B Видеокамера HDCVI купольная, 1/2.7" 1Мп | C7: 5 | D7: 795 | E7: =C7*D7 -> 3975
A8: 7 | B8: EZ-HAC-T2A21P-0280B 2Мп Видеокамера HDCVI купольная | C8: 10 | D8: 1045 | E8: =C8*D8 -> 10450
A9: 8 | B9: EZ-HAC-T5B20P-A-0280B Видеокамера HDCVI купольная, 1/2.7" 2Мп | C9: 10 | D9: 1295 | E9: =C9*D9 -> 12950
A10: 9 | B10: EZ-HAC-T6B20P-LED-0280B Видеокамера HDCVI купольная, 2Мп | C10: 10 | D10: 1245 | E10: =C10*D10 -> 12450
A11: 10 | B11: EZ-IPC-B1B20P-0360B IP-видеокамера | C11: 1 | D11: 2295 | E11: =C11*D11 -> 2295
A12: 11 | B12: EZ-NVR1B04 4-канальный сетевой видеорегистратор | C12: 2 | D12: 2195 | E12: =C12*D12 -> 4390
A13: 12 | B13: EZ-NVR1B04HC/E Видеорегистратор наблюдения Dahua | C13: 1 | D13: 2595 | E13: =C13*D13 -> 2595
A14: 13 | B14: EZ-NVR1B08HS Видеорегистратор наблюдения | C14: 4 | D14: 3895 | E14: =C14*D14 -> 15580
A15: 14 | B15: EZ-NVR2B16 IP видеорегистратор Dahua | C15: 3 | D15: 5295 | E15: =C15*D15 -> 15885
... A18: 17 | B18: EZ-XVR1B16H Гибридный регистратор | C18: 3 | D18: 6495 | E18: =C18*D18 -> 19485
F19: сумма: | G19: =SUM(E20:E37) -> 143663
A20: 18 | B20: IP-видеокамера купольная антивандальная DH-IPC-HDBW1431EP-S-0360B | C20: 3 | D20: 4300 | E20: =C20*D20 -> 12900
A21: 19 | B21: DH-IPC-HDBW4231FP-AS-0280B 2Мп IP видеокамера | C21: 2 | D21: 4700 | E21: =C21*D21 -> 9400
A22: 20 | B22: Миниатюрная IP видеокамера DH-IPC-K35AP 3MP c POE | C22: 5 | D22: 3500 | E22: =C22*D22 -> 17500
A23: 21 | B23: IP-видеокамера DH-IPC-K35P для системы видеонаблюдения | C23: 1 | D23: 3500 | E23: =C23*D23 -> 3500
A24: 22 | B24: Уличная поворотная купольная HDCVI видеокамера DH-SD22204I-GC для систем видеонаблюдения | C24: 1 | D24: 5300 | E24: =C24*D24 -> 5300
A25: 23 | B25: DHI-VTH1550CH Монитор IP домофона DAHUA цветной сенсорный | C25: 1 | D25: 7145 | E25: =C25*D25 -> 7145
A26: 24 | B26: DHI-ASI1201A-D контролер | C26: 1 | D26: 3495 | E26: =C26*D26 -> 3495
A27: 25 | B27: DH-ASR1101A-D RFID считыватель | C27: 1 | D27: 1645 | E27: =C27*D27 -> 1645
A28: 26 | B28: IP видеорегистратор DHI-NVR2104-4KS2 | C28: 1 | D28: 2995 | E28: =C28*D28 -> 2995
A29: 27 | B29: IP видеорегистратор DHI-NVR2104-W-4KS2 | C29: 1 | D29: 4800 | E29: =C29*D29 -> 4800
A30: 28 | B30: IP видеорегистратор DHI-NVR2108-4KS2 | C30: 1 | D30: 3995 | E30: =C30*D30 -> 3995
A31: 29 | B31: 16-канальный 4K сетевой видеорегистратор Dahua DH-NVR4216-4KS2 | C31: 1 | D31: 8095 | E31: =C31*D31 -> 8095
... A37: 35 | B37: Видеокамера IP Уличная цилиндрическая 2Mп DH-IPC-HFW2230SP-S-0360B | C37: 3 | D37: 3845 | E37: =C37*D37 -> 11535
F38: сумма: | G38: =SUM(E39) -> 25000
A39: 36 | B39: Замки | C39: 1 | D39: 25000 | E39: =C39*D39 -> 25000
F40: сумма: | G40: =SUM(E41:E62) -> 286485
A41: 37 | B41: HiWatch DS-N332/2(B) 32-х канальный IP-регистратор | C41: 1 | D41: 10995 | E41: =C41*D41 -> 10995
A42: 38 | B42: HiWatch DS-I250 (2.8 mm) 2Мп уличная цилиндрическая IP-камера | C42: 10 | D42: 3460 | E42: =C42*D42 -> 34600
A43: 39 | B43: HiWatch IPC-B020 (2.8mm) 2Мп уличная цилиндрическая IP-камера | C43: 5 | D43: 2415 | E43: =C43*D43 -> 12075
A44: 40 | B44: HiWatch IPC-T020 (2.8mm) 2Мп уличная купольная IP-камера | C44: 5 | D44: 2415 | E44: =C44*D44 -> 12075
A45: 41 | B45: HiWatch DS-S908P(B) Сетевой неуправляемый коммутатор | C45: 1 | D45: 3020 | E45: =C45*D45 -> 3020
A46: 42 | B46: HiWatch DS-S604P Сетевой неуправляемый коммутатор | C46: 1 | D46: 1945 | E46: =C46*D46 -> 1945
A47: 43 | B47: HiWatch DS-D100MF 7" цветной TFT монитор 800х480 c памятью до 200 снимков | C47: 1 | D47: 3570 | E47: =C47*D47 -> 3570
...

Sheet Расчеты
A1: Tаблица 1
D5: Розница | E5: Приращение | F5: Сумма приращение | G5: Средняя скидка | H5: Сумма со скидкой | I5: Возврат на склад | K5: сумма: | L5: =SUM(J6:J22) -> 304420 | M5: Возврат на склад: | N5: =SUM(I6:I22) -> 182652 | O5: С 25% скидки | P5: =SUM(H6:H22) -> 197873 | Q5: Сумма по рознице: | R5: =SUM(L6:L78) -> 910296 | S5: Сумма закупки | T5: =Приход!J1 -> 722198
A6: 1 | B6: EZ-HAC-B2A41P-0280B-DIP Видеокамера HDCVI купольная, 1/2.7" 4Мп | C6: 1 | D6: =Приход!$D2*2 -> 2990 | E6: =Приход!D2*$T$16 -> 1734.2 | F6: =E6*C6 -> 1734.2 | G6: =D6*$T$15 -> 1943.5 | H6: =G6*C6 -> 1943.5 | I6: =D6*0.6*Приход!C2 -> 1794 | J6: =C6*D6 -> 2990 | Q6: взято на закупку: | R6: 700000 | S6: Сумма возврата на склад: | T6: =N$5+N23+N42+N44 -> 728829.6
A7: 2 | B7: EZ-HAC-B6B20P-LED-0360B Видеокамера HDCVI цилиндрическая, 1/2.8" 2Мп | C7: 2 | D7: =Приход!$D3*2 -> 2790 | E7: =Приход!D3*$T$16 -> 1618.2 | F7: =E7*C7 -> 3236.4 | G7: =D7*$T$15 -> 1813.5 | H7: =G7*C7 -> 3627 | I7: =D7*0.6*Приход!C3 -> 3348 | J7: =C7*D7 -> 5580 | Q7: остаток: | R7: =R6-R5 -> -210296 | S7: Сумма продаж со средней скидкой | T7: =P$5+P23+P42+P44 -> 789565.4
A8: 3 | B8: EZ-HAC-D1A21P-0280B 2Мп HD-CVI камера видеонаблюдения | C8: 10 | D8: =Приход!$D4*2 -> 1990 | E8: =Приход!D4*$T$16 -> 1154.2 | F8: =E8*C8 -> 11542 | G8: =D8*$T$15 -> 1293.5 | H8: =G8*C8 -> 12935 | I8: =D8*0.6*Приход!C4 -> 11940 | J8: =C8*D8 -> 19900 | S8: Разница на фирме | T8: =T7-T$6 -> 60735.8
A9: 4 | B9: EZ-HAC-D1A41P-0280B 4Мп HDCVI видеокамера | C9: 5 | D9: =Приход!$D5*2 -> 2790 | E9: =Приход!D5*$T$16 -> 1618.2 | F9: =E9*C9 -> 8091 | G9: =D9*$T$15 -> 1813.5 | H9: =G9*C9 -> 9067.5 | I9: =D9*0.6*Приход!C5 -> 8370 | J9: =C9*D9 -> 13950
A10: 5 | B10: EZ-HAC-D1A41P-0360B 4Мп HDCVI видеокамера | C10: 5 | D10: =Приход!$D6*2 -> 2790 | E10: =Приход!D6*$T$16 -> 1618.2 | F10: =E10*C10 -> 8091 | G10: =D10*$T$15 -> 1813.5 | H10: =G10*C10 -> 9067.5 | I10: =D10*0.6*Приход!C6 -> 8370 | J10: =C10*D10 -> 13950 | S10: Сумма приращение | T10: =SUM(F6:F66) -> 704535.28
A11: 6 | B11: EZ-HAC-T2A11P-0280B Видеокамера HDCVI купольная, 1/2.7" 1Мп | C11: 5 | D11: =Приход!$D7*2 -> 1590 | E11: =Приход!D7*$T$16 -> 922.2 | F11: =E11*C11 -> 4611 | G11: =D11*$T$15 -> 1033.5 | H11: =G11*C11 -> 5167.5 | I11: =D11*0.6*Приход!C7 -> 4770 | J11: =C11*D11 -> 7950 | S11: Разница на фирме через приращение | T11: =T7-T10 -> 85030.12
A12: 7 | B12: EZ-HAC-T2A21P-0280B 2Мп Видеокамера HDCVI купольная | C12: 10 | D12: =Приход!$D8*2 -> 2090 | E12: =Приход!D8*$T$16 -> 1212.2 | F12: =E12*C12 -> 12122 | G12: =D12*$T$15 -> 1358.5 | H12: =G12*C12 -> 13585 | I12: =D12*0.6*Приход!C8 -> 12540 | J12: =C12*D12 -> 20900
A13: 8 | B13: EZ-HAC-T5B20P-A-0280B Видеокамера HDCVI купольная, 1/2.7" 2Мп | C13: 10 | D13: =Приход!$D9*2 -> 2590 | E13: =Приход!D9*$T$16 -> 1502.2 | F13: =E13*C13 -> 15022 | G13: =D13*$T$15 -> 1683.5 | H13: =G13*C13 -> 16835 | I13: =D13*0.6*Приход!C9 -> 15540 | J13: =C13*D13 -> 25900
A14: 9 | B14: EZ-HAC-T6B20P-LED-0280B Видеокамера HDCVI купольная, 2Мп | C14: 10 | D14: =Приход!$D10*2 -> 2490 | E14: =Приход!D10*$T$16 -> 1444.2 | F14: =E14*C14 -> 14442 | G14: =D14*$T$15 -> 1618.5 | H14: =G14*C14 -> 16185 | I14: =D14*0.6*Приход!C10 -> 14940 | J14: =C14*D14 -> 24900
A15: 10 | B15: EZ-IPC-B1B20P-0360B IP-видеокамера | C15: 1 | D15: =Приход!$D11*2 -> 4590 | E15: =Приход!D11*$T$16 -> 2662.2 | F15: =E15*C15 -> 2662.2 | G15: =D15*$T$15 -> 2983.5 | H15: =G15*C15 -> 2983.5 | I15: =D15*0.6*Приход!C11 -> 2754 | J15: =C15*D15 -> 4590 | S15: Средняя скидка | T15: 0.65
A16: 11 | B16: EZ-NVR1B04 4-канальный сетевой видеорегистратор | C16: 2 | D16: =Приход!$D12*2 -> 4390 | E16: =Приход!D12*$T$16 -> 2546.2 | F16: =E16*C16 -> 5092.4 | G16: =D16*$T$15 -> 2853.5 | H16: =G16*C16 -> 5707 | I16: =D16*0.6*Приход!C12 -> 5268 | J16: =C16*D16 -> 8780 | S16: Процент приращения | T16: 1.16
A17: 12 | B17: EZ-NVR1B04HC/E Видеорегистратор наблюдения Dahua | C17: 1 | D17: =Приход!$D13*2 -> 5190 | E17: =Приход!D13*$T$16 -> 3010.2 | F17: =E17*C17 -> 3010.2 | G17: =D17*$T$15 -> 3373.5 | H17: =G17*C17 -> 3373.5 | I17: =D17*0.6*Приход!C13 -> 3114 | J17: =C17*D17 -> 5190
A18: 13 | B18: EZ-NVR1B08HS Видеорегистратор наблюдения | C18: 4 | D18: =Приход!$D14*2 -> 7790 | E18: =Приход!D14*$T$16 -> 4518.2 | F18: =E18*C18 -> 18072.8 | G18: =D18*$T$15 -> 5063.5 | H18: =G18*C18 -> 20254 | I18: =D18*0.6*Приход!C14 -> 18696 | J18: =C18*D18 -> 31160
A19: 14 | B19: EZ-NVR2B16 IP видеорегистратор Dahua | C19: 3 | D19: =Приход!$D15*2 -> 10590 | E19: =Приход!D15*$T$16 -> 6142.2 | F19: =E19*C19 -> 18426.6 | G19: =D19*$T$15 -> 6883.5 | H19: =G19*C19 -> 20650.5 | I19: =D19*0.6*Приход!C15 -> 19062 | J19: =C19*D19 -> 31770
A20: 15 | B20: EZ-XVR1B04H Гибридный регистратор | C20: 1 | D20: =Приход!$D16*2 -> 5490 | E20: =Приход!D16*$T$16 -> 3184.2 | F20: =E20*C20 -> 3184.2 | G20: =D20*$T$15 -> 3568.5 | H20: =G20*C20 -> 3568.5 | I20: =D20*0.6*Приход!C16 -> 3294 | J20: =C20*D20 -> 5490
A21: 16 | B21: EZ-XVR1B08H Гибридный регистратор | C21: 5 | D21: =Приход!$D17*2 -> 8490 | E21: =Приход!D17*$T$16 -> 4924.2 | F21: =E21*C21 -> 24621 | G21: =D21*$T$15 -> 5518.5 | H21: =G21*C21 -> 27592.5 | I21: =D21*0.6*Приход!C17 -> 25470 | J21: =C21*D21 -> 42450
A22: 17 | B22: EZ-XVR1B16H Гибридный регистратор | C22: 3 | D22: =Приход!$D18*2 -> 12990 | E22: =Приход!D18*$T$16 -> 7534.2 | F22: =E22*C22 -> 22602.6 | G22: =D22*$T$15 -> 8443.5 | H22: =G22*C22 -> 25330.5 | I22: =D22*0.6*Приход!C18 -> 23382 | J22: =C22*D22 -> 38970
E23: =Приход!D19*$T$16 -> 0 | F23: =E23*C23 -> 0 | G23: =D23*$T$15 -> 0 | K23: сумма: | L23: =SUM(J24:J41) -> 287326 | M23: Возврат на склад: | N23: =SUM(I24:I41) -> 172395.6 | O23: С 25% скидки | P23: =SUM(H24:H41) -> 186761.9
A24: 18 | B24: IP-видеокамера купольная антивандальная DH-IPC-HDBW1431EP-S-0360B | C24: 3 | D24: =Приход!$D20*2 -> 8600 | E24: =Приход!D20*$T$16 -> 4988 | F24: =E24*C24 -> 14964 | G24: =D24*$T$15 -> 5590 | H24: =G24*C24 -> 16770 | I24: =D24*0.6*Приход!C20 -> 15480 | J24: =C24*D24 -> 25800
A25: 19 | B25: DH-IPC-HDBW4231FP-AS-0280B 2Мп IP видеокамера | C25: 2 | D25: =Приход!$D21*2 -> 9400 | E25: =Приход!D21*$T$16 -> 5452 | F25: =E25*C25 -> 10904 | G25: =D25*$T$15 -> 6110 | H25: =G25*C25 -> 12220 | I25: =D25*0.6*Приход!C21 -> 11280 | J25: =C25*D25 -> 18800
A26: 20 | B26: Миниатюрная IP видеокамера DH-IPC-K35AP 3MP c POE | C26: 5 | D26: =Приход!$D22*2 -> 7000 | E26: =Приход!D22*$T$16 -> 4060 | F26: =E26*C26 -> 20300 | G26: =D26*$T$15 -> 4550 | H26: =G26*C26 -> 22750 | I26: =D26*0.6*Приход!C22 -> 21000 | J26: =C26*D26 -> 35000
A27: 21 | B27: IP-видеокамера DH-IPC-K35P для системы видеонаблюдения | C27: 1 | D27: =Приход!$D23*2 -> 7000 | E27: =Приход!D23*$T$16 -> 4060 | F27: =E27*C27 -> 4060 | G27: =D27*$T$15 -> 4550 | H27: =G27*C27 -> 4550 | I27: =D27*0.6*Приход!C23 -> 4200 | J27: =C27*D27 -> 7000
A28: 22 | B28: Уличная поворотная купольная HDCVI видеокамера DH-SD22204I-GC для систем видеонаблюдения | C28: 1 | D28: =Приход!$D24*2 -> 10600 | E28: =Приход!D24*$T$16 -> 6148 | F28: =E28*C28 -> 6148 | G28: =D28*$T$15 -> 6890 | H28: =G28*C28 -> 6890 | I28: =D28*0.6*Приход!C24 -> 6360 | J28: =C28*D28 -> 10600
A29: 23 | B29: DHI-VTH1550CH Монитор IP домофона DAHUA цветной сенсорный | C29: 1 | D29: =Приход!$D25*2 -> 14290 | E29: =Приход!D25*$T$16 -> 8288.2 | F29: =E29*C29 -> 8288.2 | G29: =D29*$T$15 -> 9288.5 | H29: =G29*C29 -> 9288.5 | I29: =D29*0.6*Приход!C25 -> 8574 | J29: =C29*D29 -> 14290
A30: 24 | B30: DHI-ASI1201A-D контролер | C30: 1 | D30: =Приход!$D26*2 -> 6990 | E30: =Приход!D26*$T$16 -> 4054.2 | F30: =E30*C30 -> 4054.2 | G30: =D30*$T$15 -> 4543.5 | H30: =G30*C30 -> 4543.5 | I30: =D30*0.6*Приход!C26 -> 4194 | J30: =C30*D30 -> 6990
A31: 25 | B31: DH-ASR1101A-D RFID считыватель | C31: 1 | D31: =Приход!$D27*2 -> 3290 | E31: =Приход!D27*$T$16 -> 1908.2 | F31: =E31*C31 -> 1908.2 | G31: =D31*$T$15 -> 2138.5 | H31: =G31*C31 -> 2138.5 | I31: =D31*0.6*Приход!C27 -> 1974 | J31: =C31*D31 -> 3290
A32: 26 | B32: IP видеорегистратор DHI-NVR2104-4KS2 | C32: 1 | D32: =Приход!$D28*2 -> 5990 | E32: =Приход!D28*$T$16 -> 3474.2 | F32: =E32*C32 -> 3474.2 | G32: =D32*$T$15 -> 3893.5 | H32: =G32*C32 -> 3893.5 | I32: =D32*0.6*Приход!C28 -> 3594 | J32: =C32*D32 -> 5990
A33: 27 | B33: IP видеорегистратор DHI-NVR2104-W-4KS2 | C33: 1 | D33: =Приход!$D29*2 -> 9600 | E33: =Приход!D29*$T$16 -> 5568 | F33: =E33*C33 -> 5568 | G33: =D33*$T$15 -> 6240 | H33: =G33*C33 -> 6240 | I33: =D33*0.6*Приход!C29 -> 5760 | J33: =C33*D33 -> 9600
A34: 28 | B34: IP видеорегистратор DHI-NVR2108-4KS2 | C34: 1 | D34: =Приход!$D30*2 -> 7990 | E34: =Приход!D30*$T$16 -> 4634.2 | F34: =E34*C34 -> 4634.2 | G34: =D34*$T$15 -> 5193.5 | H34: =G34*C34 -> 5193.5 | I34: =D34*0.6*Приход!C30 -> 4794 | J34: =C34*D34 -> 7990
A35: 29 | B35: 16-канальный 4K сетевой видеорегистратор Dahua DH-NVR4216-4KS2 | C35: 1 | D35: =Приход!$D31*2 -> 16190 | E35: =Приход!D31*$T$16 -> 9390.2 | F35: =E35*C35 -> 9390.2 | G35: =D35*$T$15 -> 10523.5 | H35: =G35*C35 -> 10523.5 | I35: =D35*0.6*Приход!C31 -> 9714 | J35: =C35*D35 -> 16190
... A41: 35 | B41: Видеокамера IP Уличная цилиндрическая 2Mп DH-IPC-HFW2230SP-S-0360B | C41: 3 | D41: =Приход!$D37*2 -> 7690 | E41: =Приход!D37*$T$16 -> 4460.2 | F41: =E41*C41 -> 13380.6 | G41: =D41*$T$15 -> 4998.5 | H41: =G41*C41 -> 14995.5 | I41: =D41*0.6*Приход!C37 -> 13842 | J41: =C41*D41 -> 23070
E42: =Приход!D38*$T$16 -> 0 | F42: =E42*C42 -> 0 | G42: =D42*$T$15 -> 0 | K42: сумма: | L42: =SUM(J43) -> 50000 | M42: Возврат на склад: | N42: =SUM(I43) -> 30000 | O42: С 25% скидки | P42: =SUM(H43) -> 32500
A43: 36 | B43: Замки | C43: 1 | D43: =Приход!$D39*2 -> 50000 | E43: =Приход!D39*$T$16 -> 29000 | F43: =E43*C43 -> 29000 | G43: =D43*$T$15 -> 32500 | H43: =G43*C43 -> 32500 | I43: =D43*0.6*Приход!C39 -> 30000 | J43: =C43*D43 -> 50000
E44: =Приход!D40*$T$16 -> 0 | F44: =E44*C44 -> 0 | G44: =D44*$T$15 -> 0 | K44: сумма: | L44: =SUM(J45:J66) -> 572970 | M44: Возврат на склад: | N44: =SUM(I45:I66) -> 343782 | O44: С 25% скидки | P44: =SUM(H45:H66) -> 372430.5
A45: 37 | B45: HiWatch DS-N332/2(B) 32-х канальный IP-регистратор | C45: 1 | D45: =Приход!$D41*2 -> 21990 | E45: =Приход!D41*$T$16 -> 12754.2 | F45: =E45*C45 -> 12754.2 | G45: =D45*$T$15 -> 14293.5 | H45: =G45*C45 -> 14293.5 | I45: =D45*0.6*Приход!C41 -> 13194 | J45: =C45*D45 -> 21990
A46: 38 | B46: HiWatch DS-I250 (2.8 mm) 2Мп уличная цилиндрическая IP-камера | C46: 10 | D46: =Приход!$D42*2 -> 6920 | E46: =Приход!D42*$T$16 -> 4013.6 | F46: =E46*C46 -> 40136 | G46: =D46*$T$15 -> 4498 | H46: =G46*C46 -> 44980 | I46: =D46*0.6*Приход!C42 -> 41520 | J46: =C46*D46 -> 69200
A47: 39 | B47: HiWatch IPC-B020 (2.8mm) 2Мп уличная цилиндрическая IP-камера | C47: 5 | D47: =Приход!$D43*2 -> 4830 | E47: =Приход!D43*$T$16 -> 2801.4 | F47: =E47*C47 -> 14007 | G47: =D47*$T$15 -> 3139.5 | H47: =G47*C47 -> 15697.5 | I47: =D47*0.6*Приход!C43 -> 14490 | J47: =C47*D47 -> 24150
A48: 40 | B48: HiWatch IPC-T020 (2.8mm) 2Мп уличная купольная IP-камера | C48: 5 | D48: =Приход!$D44*2 -> 4830 | E48: =Приход!D44*$T$16 -> 2801.4 | F48: =E48*C48 -> 14007 | G48: =D48*$T$15 -> 3139.5 | H48: =G48*C48 -> 15697.5 | I48: =D48*0.6*Приход!C44 -> 14490 | J48: =C48*D48 -> 24150
...

Sheet Лист2
A1: Антон желев
A2: 16 | B2: EZ-XVR1B08H Гибридный регистратор | C2: 1 | D2: 4245 | E2: =C2*D2 -> 4245 | H2: =SUM(E2:E12)/5*6 -> 37386
A3: 8 | B3: EZ-HAC-T5B20P-A-0280B Видеокамера HDCVI купольная, 1/2.7" 2Мп | C3: 1 | D3: 1295 | E3: =C3*D3 -> 1295
A4: 3 | B4: EZ-HAC-D1A21P-0280B 2Мп HD-CVI камера видеонаблюдения | C4: 7 | D4: 995 | E4: =C4*D4 -> 6965
A5: Коля Алеев
A6: 45 | B6: HiWatch DS-I200 (C) (2.8 mm) 2Мп уличная цилиндрическая IP-камера с EXIR-подсветкой | C6: 1 | D6: 2525 | E6: =C6*D6 -> 2525
A7: Балашов
A8: 21 | B8: IP-видеокамера DH-IPC-K35P для системы видеонаблюдения | C8: 1 | D8: 3500 | E8: =C8*D8 -> 3500
A9: Хабаров Андрей
A10: 45 | B10: HiWatch DS-I200 (C) (2.8 mm) 2Мп уличная цилиндрическая IP-камера с EXIR-подсветкой | C10: 3 | D10: 2525 | E10: =C10*D10 -> 7575
A11: 50 | B11: HiWatch DS-I203 (C) (2.8 mm) 2Мп уличная IP-камера с EXIR-подсветкой | C11: 2 | D11: 2525 | E11: =C11*D11 -> 5050
